Workbook

Sheet Cover
B2: Telecom & IT — Operating Model
B3: Author: Togrul Mirzayev • Generated: 2026-05-24
B5: PORTFOLIO
B6: https://jackidefi.github.io/finance-portfolio/
B8: MODEL MAP
B10: Assumptions | C10: Every driver and Y0 starting balance — blue cells, change freely.
B11: Drivers | C11: Subscriber and ARPU buildup; service revenue ties back to Assumptions.
B12: IS | C12: Income Statement, fully formula-driven, Y1-Y5.
B13: BS | C13: Balance Sheet, Y0 opening + Y1-Y5 forecast. Must balance.
B14: CFS | C14: Cash Flow Statement, indirect method. Ties to change in cash on BS.
B15: Equity | C15: Equity rollforward — share capital, retained earnings, OCI, minority.
B16: Debt | C16: Debt schedule — gross debt, interest, period movements.
B17: PPE | C17: PP&E rollforward — capex in, D&A out, closing balance to BS.
B18: WC | C18: Working capital schedule — AR, inventory, AP from days ratios.
B19: Tax | C19: Tax expense schedule — current tax, effective rate.
B20: Budget | C20: Y1 broken into 12 months with quarterly subtotals (planning view).
B21: Scenarios | C21: Downside / Base / Upside switcher; flexes growth, margin, capex.
... B24: Checks | C24: BS balance, CFS reconciliation, cash positivity, sources = uses.
B27: COLOUR LEGEND
B28: Blue | C28: Hard-coded input — change freely.
B29: Black | C29: Formula referencing other cells.
B30: Bold | C30: Subtotal or key model output.
B31: Green / red fills | C31: Checks sheet — pass / fail status.
B33: DATA SOURCES
B34: Y0 inputs calibrated to STC's FY2024 actuals. Revenue (SAR 75.9 bn) and balance-sheet items (cash 13.4, AR 35.0, PP&E 43.3, intangibles 17.3, investments 34.3, AP 7.5, ST debt 3.0, LT debt 14.0, lease liab 1.7, share capital 50.0, equity 86.4) are drawn from STC's FY2024 consolidated balance sheet (per IR release dated 25-Feb-2025 and the FY2024 annual report). Segment splits (postpaid / prepaid / fixed / B2B / ICT / wholesale), debt tranche structure, spectrum cohort assumptions, working-capital ratios and growth/margin forecast inputs are analytical estimates — STC discloses by business unit (consumer / business / wholesale), not by the analytical segments modelled here. The tranche structure (Sukuk 1/Sukuk 2/Term Loan/RCF) is an illustrative breakdown of STC's actual SAR 17 bn financial debt; STC does not publicly disclose each tranche's coupon and maturity in granular form.
B40: MODEL CONVENTIONS
B41: • All figures in SAR billion unless noted (subscribers in millions, ARPU in SAR / month).
B42: • Forecast horizon: 5 explicit years (Y1-Y5). Y0 is the base / opening period.
B43: • Interest expense uses cost-of-debt × opening total debt to avoid circular references.
B44: • Working capital is built from DSO / DIO / DPO ratios applied to revenue and COGS.
B45: • Depreciation is driven by D&A as % of revenue; PP&E rolls forward as opening + capex − D&A.
B46: • Tax is a single effective rate applied to pre-tax income; deferred tax held flat.
B47: • Dividends = payout ratio × net income; equity rolls forward through the Equity sheet.
B48: • Terminal value via Gordon growth: FCFF_Y5 × (1+g) ÷ (WACC − g).
B49: • BS plugs to cash from the CFS — if every BS movement is correctly mirrored in CFS, the BS balances.

Sheet Assumptions
A1: ASSUMPTIONS
A2: All inputs to the model live on this sheet. Change blue cells freely.
A4: Operating drivers
A5: Service revenue Y0 (SAR bn) | B5: 75.9 | C5: Year 0 base; everything scales from here.
A6: Revenue growth (annual) | B6: 0.06 | C6: Applied to every forecast year (Scenarios sheet can override).
A7: EBITDA margin (target, info only) | B7: 0.345 | C7: Reference value. Actual EBITDA is computed bottom-up from cost lines below.
A8: D&A / revenue | B8: 0.16 | C8: Drives PP&E rollforward and depreciation expense.
A9: Capex intensity | B9: 0.16 | C9: Capex ÷ revenue, fed into PP&E and CFS.
A11: Cost structure (% of revenue)
A12: COGS / interconnect / content | B12: 0.22 | C12: Variable; partly indexed to revenue.
A13: Network opex | B13: 0.14 | C13: Site lease, energy, maintenance — mostly fixed.
A14: Employee costs | B14: 0.13 | C14: Quasi-fixed.
A15: Customer acquisition / commercial | B15: 0.05 | C15: Subsidies, dealer commissions.
A16: Other opex / G&A | B16: 0.11 | C16: Catch-all; sum of all five lines + EBITDA margin should = 100%.
A17: Finance income / revenue | B17: 0.005 | C17: Treasury yield on cash and short-term investments.
A19: Financial
A20: Tax / zakat rate | B20: 0.15 | C20: Effective rate applied to pre-tax income.
A21: WACC | B21: 0.09 | C21: Discount rate for DCF.
A22: Terminal growth (g) | B22: 0.03 | C22: Long-run nominal growth; must be < WACC.
A23: Cost of debt (interest) | B23: 0.05 | C23: Applied to opening total debt for period interest.
A24: Dividend payout (% of NI) | B24: 0.5 | C24: Used to compute dividends in equity rollforward & CFS.
A26: Working capital (days)
A27: Days sales outstanding (DSO) | B27: 168 | C27: Drives accounts receivable on BS.
A28: Days inventory outstanding (DIO) | B28: 40 | C28: Drives inventory on BS.
A29: Days payables outstanding (DPO) | B29: 130 | C29: Drives accounts payable on BS.
A31: Capital structure
A32: Shares outstanding (millions) | B32: 5000 | C32: Used for per-share value.
A34: Balance sheet Y0 — Assets
A35: Cash & equivalents | B35: 13.4 | C35: Opening cash; plugs through CFS thereafter.
A36: Accounts receivable | B36: 35 | C36: Calibrated to DSO × revenue.
A37: Inventory | B37: 1.9
A38: Other current assets | B38: 7.8 | C38: Held flat in forecast.
A39: Property, plant & equipment | B39: 43.3 | C39: Net book value; rolls forward via PPE sheet.
A40: Goodwill | B40: 0 | C40: Held flat (no impairment in default case).
A41: Intangibles (incl. spectrum) | B41: 17.3 | C41: Held flat.
A42: Investments / associates | B42: 34.3
A43: Deferred tax assets | B43: 2.8 | C43: Held flat.
A45: Balance sheet Y0 — Liabilities
A46: Accounts payable | B46: 7.5 | C46: Calibrated to DPO × COGS.
A47: Other current liabilities | B47: 30
...

Sheet Drivers
A1: REVENUE & SUBSCRIBER DRIVERS
A2: Six service segments + handset revenue. Subs / ARPU / churn dynamics for consumer mobile and fixed; direct-revenue modeling for B2B, ICT and wholesale.
B4: Y0 (base) | C4: Y1 | D4: Y2 | E4: Y3 | F4: Y4 | G4: Y5
A6: SUBSCRIBER DYNAMICS (millions)
A7: Mobile postpaid
A8: Opening subscribers | B8: "" | C8: =Assumptions!$B$65 | D8: =C11 | E8: =D11 | F8: =E11 | G8: =F11
A9: + Gross adds | C9: =Assumptions!$B$67*C8 | D9: =Assumptions!$B$67*D8 | E9: =Assumptions!$B$67*E8 | F9: =Assumptions!$B$67*F8 | G9: =Assumptions!$B$67*G8
A10: − Churn (× opening base) | C10: =-Assumptions!$B$68*C8 | D10: =-Assumptions!$B$68*D8 | E10: =-Assumptions!$B$68*E8 | F10: =-Assumptions!$B$68*F8 | G10: =-Assumptions!$B$68*G8
A11: Closing subscribers | B11: =Assumptions!$B$65 | C11: =C8+C9+C10 | D11: =D8+D9+D10 | E11: =E8+E9+E10 | F11: =F8+F9+F10 | G11: =G8+G9+G10
A13: Mobile prepaid
A14: Opening subscribers | B14: "" | C14: =Assumptions!$B$73 | D14: =C17 | E14: =D17 | F14: =E17 | G14: =F17
A15: + Gross adds | C15: =Assumptions!$B$75*C14 | D15: =Assumptions!$B$75*D14 | E15: =Assumptions!$B$75*E14 | F15: =Assumptions!$B$75*F14 | G15: =Assumptions!$B$75*G14
A16: − Churn (× opening base) | C16: =-Assumptions!$B$76*C14 | D16: =-Assumptions!$B$76*D14 | E16: =-Assumptions!$B$76*E14 | F16: =-Assumptions!$B$76*F14 | G16: =-Assumptions!$B$76*G14
A17: Closing subscribers | B17: =Assumptions!$B$73 | C17: =C14+C15+C16 | D17: =D14+D15+D16 | E17: =E14+E15+E16 | F17: =F14+F15+F16 | G17: =G14+G15+G16
A19: Fixed broadband
A20: Opening subscribers | B20: "" | C20: =Assumptions!$B$81 | D20: =C23 | E20: =D23 | F20: =E23 | G20: =F23
A21: + Gross adds | C21: =Assumptions!$B$83*C20 | D21: =Assumptions!$B$83*D20 | E21: =Assumptions!$B$83*E20 | F21: =Assumptions!$B$83*F20 | G21: =Assumptions!$B$83*G20
A22: − Churn (× opening base) | C22: =-Assumptions!$B$84*C20 | D22: =-Assumptions!$B$84*D20 | E22: =-Assumptions!$B$84*E20 | F22: =-Assumptions!$B$84*F20 | G22: =-Assumptions!$B$84*G20
A23: Closing subscribers | B23: =Assumptions!$B$81 | C23: =C20+C21+C22 | D23: =D20+D21+D22 | E23: =E20+E21+E22 | F23: =F20+F21+F22 | G23: =G20+G21+G22
A25: ARPU (SAR / month)
A26: Mobile postpaid | B26: =Assumptions!$B$66 | C26: =B26*(1+Assumptions!$B$69) | D26: =C26*(1+Assumptions!$B$69) | E26: =D26*(1+Assumptions!$B$69) | F26: =E26*(1+Assumptions!$B$69) | G26: =F26*(1+Assumptions!$B$69)
A27: Mobile prepaid | B27: =Assumptions!$B$74 | C27: =B27*(1+Assumptions!$B$77) | D27: =C27*(1+Assumptions!$B$77) | E27: =D27*(1+Assumptions!$B$77) | F27: =E27*(1+Assumptions!$B$77) | G27: =F27*(1+Assumptions!$B$77)
A28: Fixed broadband | B28: =Assumptions!$B$82 | C28: =B28*(1+Assumptions!$B$85) | D28: =C28*(1+Assumptions!$B$85) | E28: =D28*(1+Assumptions!$B$85) | F28: =E28*(1+Assumptions!$B$85) | G28: =F28*(1+Assumptions!$B$85)
A30: IMPLIED SEGMENT REVENUE (SAR bn)
A31: Mobile postpaid | B31: =B11*B26*12/1000 | C31: =C11*C26*12/1000 | D31: =D11*D26*12/1000 | E31: =E11*E26*12/1000 | F31: =F11*F26*12/1000 | G31: =G11*G26*12/1000
A32: Mobile prepaid | B32: =B17*B27*12/1000 | C32: =C17*C27*12/1000 | D32: =D17*D27*12/1000 | E32: =E17*E27*12/1000 | F32: =F17*F27*12/1000 | G32: =G17*G27*12/1000
A33: Fixed broadband | B33: =B23*B28*12/1000 | C33: =C23*C28*12/1000 | D33: =D23*D28*12/1000 | E33: =E23*E28*12/1000 | F33: =F23*F28*12/1000 | G33: =G23*G28*12/1000
A34: B2B connectivity | B34: =Assumptions!$B$89 | C34: =B34*(1+Assumptions!$B$90) | D34: =C34*(1+Assumptions!$B$90) | E34: =D34*(1+Assumptions!$B$90) | F34: =E34*(1+Assumptions!$B$90) | G34: =F34*(1+Assumptions!$B$90)
A35: ICT / cloud | B35: =Assumptions!$B$94 | C35: =B35*(1+Assumptions!$B$95) | D35: =C35*(1+Assumptions!$B$95) | E35: =D35*(1+Assumptions!$B$95) | F35: =E35*(1+Assumptions!$B$95) | G35: =F35*(1+Assumptions!$B$95)
A36: Wholesale | B36: =Assumptions!$B$99 | C36: =B36*(1+Assumptions!$B$100) | D36: =C36*(1+Assumptions!$B$100) | E36: =D36*(1+Assumptions!$B$100) | F36: =E36*(1+Assumptions!$B$100) | G36: =F36*(1+Assumptions!$B$100)
A38: TOTAL SERVICE REVENUE | B38: =B31+B32+B33+B34+B35+B36 | C38: =C31+C32+C33+C34+C35+C36 | D38: =D31+D32+D33+D34+D35+D36 | E38: =E31+E32+E33+E34+E35+E36 | F38: =F31+F32+F33+F34+F35+F36 | G38: =G31+G32+G33+G34+G35+G36
A39: Equipment / handset revenue | B39: =Assumptions!$B$104 | C39: =B39*(1+Assumptions!$B$105) | D39: =C39*(1+Assumptions!$B$105) | E39: =D39*(1+Assumptions!$B$105) | F39: =E39*(1+Assumptions!$B$105) | G39: =F39*(1+Assumptions!$B$105)
A40: TOTAL REVENUE (service + equipment) | B40: =B38+B39 | C40: =C38+C39 | D40: =D38+D39 | E40: =E38+E39 | F40: =F38+F39 | G40: =G38+G39
A42: OPERATIONAL KPIs
A43: Total mobile subscribers (mm) | B43: =B11+B17 | C43: =C11+C17 | D43: =D11+D17 | E43: =E11+E17 | F43: =F11+F17 | G43: =G11+G17
A44: Postpaid mix (% of mobile base) | B44: =B11/B43 | C44: =C11/C43 | D44: =D11/D43 | E44: =E11/E43 | F44: =F11/F43 | G44: =G11/G43
A45: Blended mobile ARPU (SAR / month) | B45: =(B31+B32)*1000/B43/12 | C45: =(C31+C32)*1000/C43/12 | D45: =(D31+D32)*1000/D43/12 | E45: =(E31+E32)*1000/E43/12 | F45: =(F31+F32)*1000/F43/12 | G45: =(G31+G32)*1000/G43/12
A46: B2B + ICT mix (% of service rev) | B46: =(B34+B35)/B38 | C46: =(C34+C35)/C38 | D46: =(D34+D35)/D38 | E46: =(E34+E35)/E38 | F46: =(F34+F35)/F38 | G46: =(G34+G35)/G38
A47: Service revenue growth (yoy) | B47: "" | C47: =C38/B38-1 | D47: =D38/C38-1 | E47: =E38/D38-1 | F47: =F38/E38-1 | G47: =G38/F38-1

Sheet Spectrum
A1: SPECTRUM LICENSE SCHEDULE
A2: Three cohorts. Cohort 1 & 2 are on the books at Y0 and amortise from there. Cohort 3 lands as a lumpy cash payment in year c3_cash_y, then amortises over its license term.
B4: Y0 (base) | C4: Y1 | D4: Y2 | E4: Y3 | F4: Y4 | G4: Y5
A6: COHORT 1 — Pre-2020 legacy 2G/3G
A7: Opening NBV | B7: "" | C7: =Assumptions!$B$124 | D7: =C9 | E7: =D9 | F7: =E9 | G7: =F9
A8: − Annual amortisation | C8: =-MIN((Assumptions!$B$124/Assumptions!$B$125),C7) | D8: =-MIN((Assumptions!$B$124/Assumptions!$B$125),D7) | E8: =-MIN((Assumptions!$B$124/Assumptions!$B$125),E7) | F8: =-MIN((Assumptions!$B$124/Assumptions!$B$125),F7) | G8: =-MIN((Assumptions!$B$124/Assumptions!$B$125),G7)
A9: Closing NBV | B9: =Assumptions!$B$124 | C9: =C7+C8 | D9: =D7+D8 | E9: =E7+E8 | F9: =F7+F8 | G9: =G7+G8
A11: COHORT 2 — 2020-2024 licenses (4G refarm + initial 5G)
A12: Opening NBV | B12: "" | C12: =Assumptions!$B$126 | D12: =C14 | E12: =D14 | F12: =E14 | G12: =F14
A13: − Annual amortisation | C13: =-MIN((Assumptions!$B$126/Assumptions!$B$127),C12) | D13: =-MIN((Assumptions!$B$126/Assumptions!$B$127),D12) | E13: =-MIN((Assumptions!$B$126/Assumptions!$B$127),E12) | F13: =-MIN((Assumptions!$B$126/Assumptions!$B$127),F12) | G13: =-MIN((Assumptions!$B$126/Assumptions!$B$127),G12)
A14: Closing NBV | B14: =Assumptions!$B$126 | C14: =C12+C13 | D14: =D12+D13 | E14: =E12+E13 | F14: =F12+F13 | G14: =G12+G13
A16: COHORT 3 — Future 5G mid-band (auction in year c3_cash_y)
A17: Cash payment (auction) | B17: =0 | C17: =IF(1=Assumptions!$B$128,Assumptions!$B$129,0) | D17: =IF(2=Assumptions!$B$128,Assumptions!$B$129,0) | E17: =IF(3=Assumptions!$B$128,Assumptions!$B$129,0) | F17: =IF(4=Assumptions!$B$128,Assumptions!$B$129,0) | G17: =IF(5=Assumptions!$B$128,Assumptions!$B$129,0)
A18: Opening NBV (+ current-year cash) | B18: =0 | C18: =0+C17 | D18: =C20+D17 | E18: =D20+E17 | F18: =E20+F17 | G18: =F20+G17
A19: − Annual amortisation | C19: =IF(C18>0,-MIN((Assumptions!$B$129/Assumptions!$B$130),C18),0) | D19: =IF(D18>0,-MIN((Assumptions!$B$129/Assumptions!$B$130),D18),0) | E19: =IF(E18>0,-MIN((Assumptions!$B$129/Assumptions!$B$130),E18),0) | F19: =IF(F18>0,-MIN((Assumptions!$B$129/Assumptions!$B$130),F18),0) | G19: =IF(G18>0,-MIN((Assumptions!$B$129/Assumptions!$B$130),G18),0)
A20: Closing NBV | B20: =0 | C20: =C18+C19 | D20: =D18+D19 | E20: =E18+E19 | F20: =F18+F19 | G20: =G18+G19
A22: TOTALS
A23: Total spectrum NBV (to BS) | B23: =B9+B14+B20 | C23: =C9+C14+C20 | D23: =D9+D14+D20 | E23: =E9+E14+E20 | F23: =F9+F14+F20 | G23: =G9+G14+G20
A24: Total amortisation (to IS) | B24: "" | C24: =C8+C13+C19 | D24: =D8+D13+D19 | E24: =E8+E13+E19 | F24: =F8+F13+F19 | G24: =G8+G13+G19
A25: Total cash payments (to CFS) | B25: "" | C25: =C17 | D25: =D17 | E25: =E17 | F25: =F17 | G25: =G17

Sheet Leases
A1: IFRS 16 LEASE SCHEDULE
A2: Right-of-use asset and lease liability rollforward. Additions are non-cash; cash payments hit CFS financing.
B4: Y0 (base) | C4: Y1 | D4: Y2 | E4: Y3 | F4: Y4 | G4: Y5
A6: RIGHT-OF-USE ASSET
A7: Opening ROU | B7: "" | C7: =Assumptions!$B$133 | D7: =C10 | E7: =D10 | F7: =E10 | G7: =F10
A8: + New lease additions | C8: =Assumptions!$B$136 | D8: =Assumptions!$B$136 | E8: =Assumptions!$B$136 | F8: =Assumptions!$B$136 | G8: =Assumptions!$B$136
A9: − ROU depreciation | C9: =-(C7+C8)/Assumptions!$B$134 | D9: =-(D7+D8)/Assumptions!$B$134 | E9: =-(E7+E8)/Assumptions!$B$134 | F9: =-(F7+F8)/Assumptions!$B$134 | G9: =-(G7+G8)/Assumptions!$B$134
A10: Closing ROU | B10: =Assumptions!$B$133 | C10: =C7+C8+C9 | D10: =D7+D8+D9 | E10: =E7+E8+E9 | F10: =F7+F8+F9 | G10: =G7+G8+G9
A12: LEASE LIABILITY
A13: Opening lease liability | B13: "" | C13: =Assumptions!$B$50 | D13: =C17 | E13: =D17 | F13: =E17 | G13: =F17
A14: + Interest accretion | C14: =C13*Assumptions!$B$135 | D14: =D13*Assumptions!$B$135 | E14: =E13*Assumptions!$B$135 | F14: =F13*Assumptions!$B$135 | G14: =G13*Assumptions!$B$135
A15: + New lease additions | C15: =C8 | D15: =D8 | E15: =E8 | F15: =F8 | G15: =G8
A16: − Cash payments | C16: =C9-C14 | D16: =D9-D14 | E16: =E9-E14 | F16: =F9-F14 | G16: =G9-G14
A17: Closing lease liability | B17: =Assumptions!$B$50 | C17: =C13+C14+C15+C16 | D17: =D13+D14+D15+D16 | E17: =E13+E14+E15+E16 | F17: =F13+F14+F15+F16 | G17: =G13+G14+G15+G16

Sheet Debt
A1: DEBT SCHEDULE — TRANCHE WATERFALL
A2: Four debt instruments. Per-tranche opening + issuance − repayment = closing. Lease liabilities live on the Leases sheet; pulled in below for total leverage view.
B4: Y0 (base) | C4: Y1 | D4: Y2 | E4: Y3 | F4: Y4 | G4: Y5
A6: TRANCHE 1 — Sukuk 1 (bullet, refinanced)
A7: Opening balance | B7: "" | C7: =Assumptions!$B$146 | D7: =C10 | E7: =D10 | F7: =E10 | G7: =F10
A8: + Issuance | C8: =IF(1=Assumptions!$B$148,Assumptions!$B$146,0) | D8: =IF(2=Assumptions!$B$148,Assumptions!$B$146,0) | E8: =IF(3=Assumptions!$B$148,Assumptions!$B$146,0) | F8: =IF(4=Assumptions!$B$148,Assumptions!$B$146,0) | G8: =IF(5=Assumptions!$B$148,Assumptions!$B$146,0)
A9: − Repayment | C9: =-IF(1=Assumptions!$B$148,Assumptions!$B$146,0) | D9: =-IF(2=Assumptions!$B$148,Assumptions!$B$146,0) | E9: =-IF(3=Assumptions!$B$148,Assumptions!$B$146,0) | F9: =-IF(4=Assumptions!$B$148,Assumptions!$B$146,0) | G9: =-IF(5=Assumptions!$B$148,Assumptions!$B$146,0)
A10: Closing balance | B10: =Assumptions!$B$146 | C10: =C7+C8+C9 | D10: =D7+D8+D9 | E10: =E7+E8+E9 | F10: =F7+F8+F9 | G10: =G7+G8+G9
A11: Interest expense (coupon × opening) | C11: =C7*Assumptions!$B$147 | D11: =D7*Assumptions!$B$147 | E11: =E7*Assumptions!$B$147 | F11: =F7*Assumptions!$B$147 | G11: =G7*Assumptions!$B$147
A13: TRANCHE 2 — Sukuk 2 (matures Y8)
A14: Opening balance | B14: "" | C14: =Assumptions!$B$151 | D14: =C17 | E14: =D17 | F14: =E17 | G14: =F17
A15: + Issuance | C15: =0 | D15: =0 | E15: =0 | F15: =0 | G15: =0
A16: − Repayment | C16: =0 | D16: =0 | E16: =0 | F16: =0 | G16: =0
A17: Closing balance | B17: =Assumptions!$B$151 | C17: =C14+C15+C16 | D17: =D14+D15+D16 | E17: =E14+E15+E16 | F17: =F14+F15+F16 | G17: =G14+G15+G16
A18: Interest expense | C18: =C14*Assumptions!$B$152 | D18: =D14*Assumptions!$B$152 | E18: =E14*Assumptions!$B$152 | F18: =F14*Assumptions!$B$152 | G18: =G14*Assumptions!$B$152
A20: TRANCHE 3 — Term loan (amortising)
A21: Opening balance | B21: "" | C21: =Assumptions!$B$155 | D21: =C24 | E21: =D24 | F21: =E24 | G21: =F24
A22: + Issuance | C22: =0 | D22: =0 | E22: =0 | F22: =0 | G22: =0
A23: − Repayment | C23: =-MIN(Assumptions!$B$157,C21) | D23: =-MIN(Assumptions!$B$157,D21) | E23: =-MIN(Assumptions!$B$157,E21) | F23: =-MIN(Assumptions!$B$157,F21) | G23: =-MIN(Assumptions!$B$157,G21)
A24: Closing balance | B24: =Assumptions!$B$155 | C24: =C21+C22+C23 | D24: =D21+D22+D23 | E24: =E21+E22+E23 | F24: =F21+F22+F23 | G24: =G21+G22+G23
A25: Interest expense | C25: =C21*Assumptions!$B$156 | D25: =D21*Assumptions!$B$156 | E25: =E21*Assumptions!$B$156 | F25: =F21*Assumptions!$B$156 | G25: =G21*Assumptions!$B$156
A27: TRANCHE 4 — RCF (drawn portion)
A28: Opening balance | B28: "" | C28: =Assumptions!$B$160 | D28: =C31 | E28: =D31 | F28: =E31 | G28: =F31
A29: + Issuance | C29: =0 | D29: =0 | E29: =0 | F29: =0 | G29: =0
A30: − Repayment | C30: =0 | D30: =0 | E30: =0 | F30: =0 | G30: =0
A31: Closing balance | B31: =Assumptions!$B$160 | C31: =C28+C29+C30 | D31: =D28+D29+D30 | E31: =E28+E29+E30 | F31: =F28+F29+F30 | G31: =G28+G29+G30
A32: Interest expense | C32: =C28*Assumptions!$B$161 | D32: =D28*Assumptions!$B$161 | E32: =E28*Assumptions!$B$161 | F32: =F28*Assumptions!$B$161 | G32: =G28*Assumptions!$B$161
A34: TOTAL FINANCIAL DEBT (excl. leases)
A35: Short-term debt (Term Loan + RCF) | B35: =Assumptions!$B$48 | C35: =C24+C31 | D35: =D24+D31 | E35: =E24+E31 | F35: =F24+F31 | G35: =G24+G31
A36: Long-term debt (Sukuk 1 + Sukuk 2) | B36: =Assumptions!$B$49 | C36: =C10+C17 | D36: =D10+D17 | E36: =E10+E17 | F36: =F10+F17 | G36: =G10+G17
A37: Lease liabilities (from Leases sheet) | B37: =Leases!$B$17 | C37: =Leases!$C$17 | D37: =Leases!$D$17 | E37: =Leases!$E$17 | F37: =Leases!$F$17 | G37: =Leases!$G$17
A39: Gross debt (total, incl. leases) | B39: =B35+B36+B37 | C39: =C35+C36+C37 | D39: =D35+D36+D37 | E39: =E35+E36+E37 | F39: =F35+F36+F37 | G39: =G35+G36+G37
A41: Less: cash (from BS) | B41: =-Assumptions!$B$35 | C41: =-BS!C7 | D41: =-BS!D7 | E41: =-BS!E7 | F41: =-BS!F7 | G41: =-BS!G7
A43: Net debt | B43: =B39+B41 | C43: =C39+C41 | D43: =D39+D41 | E43: =E39+E41 | F43: =F39+F41 | G43: =G39+G41
A45: Total financial interest (sum of tranches) | C45: =C11+C18+C25+C32 | D45: =D11+D18+D25+D32 | E45: =E11+E18+E25+E32 | F45: =F11+F18+F25+F32 | G45: =G11+G18+G25+G32
A46: Net debt issuance (to CFS) | B46: "" | C46: =C8+C9+C15+C16+C22+C23+C29+C30 | D46: =D8+D9+D15+D16+D22+D23+D29+D30 | E46: =E8+E9+E15+E16+E22+E23+E29+E30 | F46: =F8+F9+F15+F16+F22+F23+F29+F30 | G46: =G8+G9+G15+G16+G22+G23+G29+G30
A48: MATURITY PROFILE — principal payments by year
A49: Principal due | C49: =-C9+-C16+-C23+-C30 | D49: =-D9+-D16+-D23+-D30 | E49: =-E9+-E16+-E23+-E30 | F49: =-F9+-F16+-F23+-F30 | G49: =-G9+-G16+-G23+-G30
A50: Sukuk 1 | C50: =-C9 | D50: =-D9 | E50: =-E9 | F50: =-F9 | G50: =-G9
A51: Sukuk 2 | C51: =-C16 | D51: =-D16 | E51: =-E16 | F51: =-F16 | G51: =-G16
...

Sheet PPE
A1: PP&E ROLLFORWARD — by asset class
A2: Five classes: network/infrastructure, towers/sites, buildings/land, IT/equipment, vehicles/other. Each has its own useful life and capex share. Class capex = capex_share × total capex (where total = capex_pct × revenue).
B4: Y0 (base) | C4: Y1 | D4: Y2 | E4: Y3 | F4: Y4 | G4: Y5
A6: Class 1 — Network & infrastructure
A7: Opening NBV | B7: "" | C7: =Assumptions!$B$168 | D7: =C10 | E7: =D10 | F7: =E10 | G7: =F10
A8: + Capex (share × total) | C8: =Assumptions!$B$170*Assumptions!$B$9*IS!$C$14 | D8: =Assumptions!$B$170*Assumptions!$B$9*IS!$D$14 | E8: =Assumptions!$B$170*Assumptions!$B$9*IS!$E$14 | F8: =Assumptions!$B$170*Assumptions!$B$9*IS!$F$14 | G8: =Assumptions!$B$170*Assumptions!$B$9*IS!$G$14
A9: − Depreciation (NBV / life) | C9: =-C7/Assumptions!$B$169 | D9: =-D7/Assumptions!$B$169 | E9: =-E7/Assumptions!$B$169 | F9: =-F7/Assumptions!$B$169 | G9: =-G7/Assumptions!$B$169
A10: Closing NBV | B10: =Assumptions!$B$168 | C10: =C7+C8+C9 | D10: =D7+D8+D9 | E10: =E7+E8+E9 | F10: =F7+F8+F9 | G10: =G7+G8+G9
A12: Class 2 — Towers & sites
A13: Opening NBV | B13: "" | C13: =Assumptions!$B$173 | D13: =C16 | E13: =D16 | F13: =E16 | G13: =F16
A14: + Capex (share × total) | C14: =Assumptions!$B$175*Assumptions!$B$9*IS!$C$14 | D14: =Assumptions!$B$175*Assumptions!$B$9*IS!$D$14 | E14: =Assumptions!$B$175*Assumptions!$B$9*IS!$E$14 | F14: =Assumptions!$B$175*Assumptions!$B$9*IS!$F$14 | G14: =Assumptions!$B$175*Assumptions!$B$9*IS!$G$14
A15: − Depreciation (NBV / life) | C15: =-C13/Assumptions!$B$174 | D15: =-D13/Assumptions!$B$174 | E15: =-E13/Assumptions!$B$174 | F15: =-F13/Assumptions!$B$174 | G15: =-G13/Assumptions!$B$174
A16: Closing NBV | B16: =Assumptions!$B$173 | C16: =C13+C14+C15 | D16: =D13+D14+D15 | E16: =E13+E14+E15 | F16: =F13+F14+F15 | G16: =G13+G14+G15
A18: Class 3 — Buildings & land
A19: Opening NBV | B19: "" | C19: =Assumptions!$B$178 | D19: =C22 | E19: =D22 | F19: =E22 | G19: =F22
A20: + Capex (share × total) | C20: =Assumptions!$B$180*Assumptions!$B$9*IS!$C$14 | D20: =Assumptions!$B$180*Assumptions!$B$9*IS!$D$14 | E20: =Assumptions!$B$180*Assumptions!$B$9*IS!$E$14 | F20: =Assumptions!$B$180*Assumptions!$B$9*IS!$F$14 | G20: =Assumptions!$B$180*Assumptions!$B$9*IS!$G$14
A21: − Depreciation (NBV / life) | C21: =-C19/Assumptions!$B$179 | D21: =-D19/Assumptions!$B$179 | E21: =-E19/Assumptions!$B$179 | F21: =-F19/Assumptions!$B$179 | G21: =-G19/Assumptions!$B$179
A22: Closing NBV | B22: =Assumptions!$B$178 | C22: =C19+C20+C21 | D22: =D19+D20+D21 | E22: =E19+E20+E21 | F22: =F19+F20+F21 | G22: =G19+G20+G21
A24: Class 4 — IT & equipment
A25: Opening NBV | B25: "" | C25: =Assumptions!$B$183 | D25: =C28 | E25: =D28 | F25: =E28 | G25: =F28
A26: + Capex (share × total) | C26: =Assumptions!$B$185*Assumptions!$B$9*IS!$C$14 | D26: =Assumptions!$B$185*Assumptions!$B$9*IS!$D$14 | E26: =Assumptions!$B$185*Assumptions!$B$9*IS!$E$14 | F26: =Assumptions!$B$185*Assumptions!$B$9*IS!$F$14 | G26: =Assumptions!$B$185*Assumptions!$B$9*IS!$G$14
A27: − Depreciation (NBV / life) | C27: =-C25/Assumptions!$B$184 | D27: =-D25/Assumptions!$B$184 | E27: =-E25/Assumptions!$B$184 | F27: =-F25/Assumptions!$B$184 | G27: =-G25/Assumptions!$B$184
A28: Closing NBV | B28: =Assumptions!$B$183 | C28: =C25+C26+C27 | D28: =D25+D26+D27 | E28: =E25+E26+E27 | F28: =F25+F26+F27 | G28: =G25+G26+G27
A30: Class 5 — Vehicles & other
A31: Opening NBV | B31: "" | C31: =Assumptions!$B$188 | D31: =C34 | E31: =D34 | F31: =E34 | G31: =F34
A32: + Capex (share × total) | C32: =Assumptions!$B$190*Assumptions!$B$9*IS!$C$14 | D32: =Assumptions!$B$190*Assumptions!$B$9*IS!$D$14 | E32: =Assumptions!$B$190*Assumptions!$B$9*IS!$E$14 | F32: =Assumptions!$B$190*Assumptions!$B$9*IS!$F$14 | G32: =Assumptions!$B$190*Assumptions!$B$9*IS!$G$14
A33: − Depreciation (NBV / life) | C33: =-C31/Assumptions!$B$189 | D33: =-D31/Assumptions!$B$189 | E33: =-E31/Assumptions!$B$189 | F33: =-F31/Assumptions!$B$189 | G33: =-G31/Assumptions!$B$189
A34: Closing NBV | B34: =Assumptions!$B$188 | C34: =C31+C32+C33 | D34: =D31+D32+D33 | E34: =E31+E32+E33 | F34: =F31+F32+F33 | G34: =G31+G32+G33
A36: TOTAL PP&E
A37: Total opening NBV | C37: =C7+C13+C19+C25+C31 | D37: =D7+D13+D19+D25+D31 | E37: =E7+E13+E19+E25+E31 | F37: =F7+F13+F19+F25+F31 | G37: =G7+G13+G19+G25+G31
A38: + Total capex | C38: =C8+C14+C20+C26+C32 | D38: =D8+D14+D20+D26+D32 | E38: =E8+E14+E20+E26+E32 | F38: =F8+F14+F20+F26+F32 | G38: =G8+G14+G20+G26+G32
A39: − Total depreciation | C39: =C9+C15+C21+C27+C33 | D39: =D9+D15+D21+D27+D33 | E39: =E9+E15+E21+E27+E33 | F39: =F9+F15+F21+F27+F33 | G39: =G9+G15+G21+G27+G33
A40: Total closing PP&E | B40: =Assumptions!$B$39 | C40: =C10+C16+C22+C28+C34 | D40: =D10+D16+D22+D28+D34 | E40: =E10+E16+E22+E28+E34 | F40: =F10+F16+F22+F28+F34 | G40: =G10+G16+G22+G28+G34
A42: CAPEX SPLIT — maintenance vs growth
A43: Maintenance capex | C43: =C38*Assumptions!$B$140 | D43: =D38*Assumptions!$B$140 | E43: =E38*Assumptions!$B$140 | F43: =F38*Assumptions!$B$140 | G43: =G38*Assumptions!$B$140
A44: Growth capex | C44: =C38*(1-Assumptions!$B$140) | D44: =D38*(1-Assumptions!$B$140) | E44: =E38*(1-Assumptions!$B$140) | F44: =F38*(1-Assumptions!$B$140) | G44: =G38*(1-Assumptions!$B$140)
A45: Implied blended dep rate (memo) | C45: =-C39/C37 | D45: =-D39/D37 | E45: =-E39/E37 | F45: =-F39/F37 | G45: =-G39/G37

Sheet WC
A1: WORKING CAPITAL SCHEDULE
A2: AR = DSO × revenue / 365. Inventory = DIO × COGS / 365. AP = DPO × COGS / 365.
B4: Y0 (base) | C4: Y1 | D4: Y2 | E4: Y3 | F4: Y4 | G4: Y5
A6: Reference
A7: Revenue | B7: =Assumptions!$B$5 | C7: =IS!$C$14 | D7: =IS!$D$14 | E7: =IS!$E$14 | F7: =IS!$F$14 | G7: =IS!$G$14
A8: COGS (positive) | B8: =Assumptions!$B$12*Assumptions!$B$5 | C8: =Assumptions!$B$12*IS!$C$14 | D8: =Assumptions!$B$12*IS!$D$14 | E8: =Assumptions!$B$12*IS!$E$14 | F8: =Assumptions!$B$12*IS!$F$14 | G8: =Assumptions!$B$12*IS!$G$14
A10: Working capital balances (closing)
A11: Accounts receivable | B11: =Assumptions!$B$36 | C11: =Assumptions!$B$27*C7/365 | D11: =Assumptions!$B$27*D7/365 | E11: =Assumptions!$B$27*E7/365 | F11: =Assumptions!$B$27*F7/365 | G11: =Assumptions!$B$27*G7/365
A12: Inventory | B12: =Assumptions!$B$37 | C12: =Assumptions!$B$28*C8/365 | D12: =Assumptions!$B$28*D8/365 | E12: =Assumptions!$B$28*E8/365 | F12: =Assumptions!$B$28*F8/365 | G12: =Assumptions!$B$28*G8/365
A13: Accounts payable | B13: =Assumptions!$B$46 | C13: =Assumptions!$B$29*C8/365 | D13: =Assumptions!$B$29*D8/365 | E13: =Assumptions!$B$29*E8/365 | F13: =Assumptions!$B$29*F8/365 | G13: =Assumptions!$B$29*G8/365
A15: Working capital movements (to CFS)
A16: ΔReceivables (incr = use of cash) | C16: =-(C11-B11) | D16: =-(D11-C11) | E16: =-(E11-D11) | F16: =-(F11-E11) | G16: =-(G11-F11)
A17: ΔInventory (incr = use of cash) | C17: =-(C12-B12) | D17: =-(D12-C12) | E17: =-(E12-D12) | F17: =-(F12-E12) | G17: =-(G12-F12)
A18: ΔPayables (incr = source of cash) | C18: =(C13-B13) | D18: =(D13-C13) | E18: =(E13-D13) | F18: =(F13-E13) | G18: =(G13-F13)
A20: Total Δ working capital | C20: =C16+C17+C18 | D20: =D16+D17+D18 | E20: =E16+E17+E18 | F20: =F16+F17+F18 | G20: =G16+G17+G18

Sheet Tax
A1: TAX SCHEDULE — current + deferred
A2: Current tax = effective rate × pre-tax income. Deferred tax driven by PP&E book-vs-tax depreciation timing.
C4: Y1 | D4: Y2 | E4: Y3 | F4: Y4 | G4: Y5
A6: CURRENT TAX
A7: Pre-tax income (from IS) | C7: =IS!$C$37 | D7: =IS!$D$37 | E7: =IS!$E$37 | F7: =IS!$F$37 | G7: =IS!$G$37
A8: Effective tax rate | C8: =Assumptions!$B$20 | D8: =Assumptions!$B$20 | E8: =Assumptions!$B$20 | F8: =Assumptions!$B$20 | G8: =Assumptions!$B$20
A9: Current tax expense | C9: =MAX(0,C7*C8) | D9: =MAX(0,D7*D8) | E9: =MAX(0,E7*E8) | F9: =MAX(0,F7*F8) | G9: =MAX(0,G7*G8)
A11: DEFERRED TAX (PP&E book vs tax depreciation)
A12: Book depreciation (PP&E) | C12: =-PPE!$C$39 | D12: =-PPE!$D$39 | E12: =-PPE!$E$39 | F12: =-PPE!$F$39 | G12: =-PPE!$G$39
A13: Tax depreciation (accelerated) | C13: =Assumptions!$B$164*PPE!$B$40 | D13: =Assumptions!$B$164*PPE!$C$40 | E13: =Assumptions!$B$164*PPE!$D$40 | F13: =Assumptions!$B$164*PPE!$E$40 | G13: =Assumptions!$B$164*PPE!$F$40
A14: Timing difference (tax > book) | C14: =C13-C12 | D14: =D13-D12 | E14: =E13-E12 | F14: =F13-F12 | G14: =G13-G12
A15: Deferred tax expense (= timing × rate) | C15: =C14*C8 | D15: =D14*D8 | E15: =E14*E8 | F15: =F14*F8 | G15: =G14*G8
A16: Closing DTL (rollforward) | C16: =Assumptions!$B$52+C15 | D16: =C16+D15 | E16: =D16+E15 | F16: =E16+F15 | G16: =F16+G15
A18: TOTAL TAX EXPENSE (current + deferred) | C18: =C9+C15 | D18: =D9+D15 | E18: =E9+E15 | F18: =F9+F15 | G18: =G9+G15
A19: Effective tax rate (incl. deferred) | C19: =C18/C7 | D19: =D18/D7 | E19: =E18/E7 | F19: =F18/F7 | G19: =G18/G7

Sheet IS
A1: INCOME STATEMENT
A2: Segment-disclosed revenue + 10-line cost split + finance items + tax + attributable NI + EPS. All figures SAR billion, EPS in SAR.
C4: Y1 | D4: Y2 | E4: Y3 | F4: Y4 | G4: Y5
A5: REVENUE
A6: Mobile postpaid | C6: =Drivers!$C$31 | D6: =Drivers!$D$31 | E6: =Drivers!$E$31 | F6: =Drivers!$F$31 | G6: =Drivers!$G$31
A7: Mobile prepaid | C7: =Drivers!$C$32 | D7: =Drivers!$D$32 | E7: =Drivers!$E$32 | F7: =Drivers!$F$32 | G7: =Drivers!$G$32
A8: Fixed broadband | C8: =Drivers!$C$33 | D8: =Drivers!$D$33 | E8: =Drivers!$E$33 | F8: =Drivers!$F$33 | G8: =Drivers!$G$33
A9: B2B connectivity | C9: =Drivers!$C$34 | D9: =Drivers!$D$34 | E9: =Drivers!$E$34 | F9: =Drivers!$F$34 | G9: =Drivers!$G$34
A10: ICT / cloud | C10: =Drivers!$C$35 | D10: =Drivers!$D$35 | E10: =Drivers!$E$35 | F10: =Drivers!$F$35 | G10: =Drivers!$G$35
A11: Wholesale | C11: =Drivers!$C$36 | D11: =Drivers!$D$36 | E11: =Drivers!$E$36 | F11: =Drivers!$F$36 | G11: =Drivers!$G$36
A12: Total service revenue | C12: =C6+C7+C8+C9+C10+C11 | D12: =D6+D7+D8+D9+D10+D11 | E12: =E6+E7+E8+E9+E10+E11 | F12: =F6+F7+F8+F9+F10+F11 | G12: =G6+G7+G8+G9+G10+G11
A13: Equipment / handset revenue | C13: =Drivers!$C$39 | D13: =Drivers!$D$39 | E13: =Drivers!$E$39 | F13: =Drivers!$F$39 | G13: =Drivers!$G$39
A14: TOTAL REVENUE | C14: =C12+C13 | D14: =D12+D13 | E14: =E12+E13 | F14: =F12+F13 | G14: =G12+G13
A16: OPERATING COSTS
A17: Interconnect & roaming | C17: =-Assumptions!$B$109*C14 | D17: =-Assumptions!$B$109*D14 | E17: =-Assumptions!$B$109*E14 | F17: =-Assumptions!$B$109*F14 | G17: =-Assumptions!$B$109*G14
A18: Content / OTT licensing | C18: =-Assumptions!$B$110*C14 | D18: =-Assumptions!$B$110*D14 | E18: =-Assumptions!$B$110*E14 | F18: =-Assumptions!$B$110*F14 | G18: =-Assumptions!$B$110*G14
A19: Equipment COGS | C19: =-C13*(1-Assumptions!$B$106) | D19: =-D13*(1-Assumptions!$B$106) | E19: =-E13*(1-Assumptions!$B$106) | F19: =-F13*(1-Assumptions!$B$106) | G19: =-G13*(1-Assumptions!$B$106)
A20: Network energy + site lease | C20: =-Assumptions!$B$111*C14 | D20: =-Assumptions!$B$111*D14 | E20: =-Assumptions!$B$111*E14 | F20: =-Assumptions!$B$111*F14 | G20: =-Assumptions!$B$111*G14
A21: Other network opex | C21: =-Assumptions!$B$112*C14 | D21: =-Assumptions!$B$112*D14 | E21: =-Assumptions!$B$112*E14 | F21: =-Assumptions!$B$112*F14 | G21: =-Assumptions!$B$112*G14
A22: Employee costs | C22: =-Assumptions!$B$14*C14 | D22: =-Assumptions!$B$14*D14 | E22: =-Assumptions!$B$14*E14 | F22: =-Assumptions!$B$14*F14 | G22: =-Assumptions!$B$14*G14
A23: Customer acquisition (commissions, subsidies) | C23: =-Assumptions!$B$15*C14 | D23: =-Assumptions!$B$15*D14 | E23: =-Assumptions!$B$15*E14 | F23: =-Assumptions!$B$15*F14 | G23: =-Assumptions!$B$15*G14
A24: Other commercial / marketing | C24: =-Assumptions!$B$113*C14 | D24: =-Assumptions!$B$113*D14 | E24: =-Assumptions!$B$113*E14 | F24: =-Assumptions!$B$113*F14 | G24: =-Assumptions!$B$113*G14
A25: G&A / overhead | C25: =-Assumptions!$B$114*C14 | D25: =-Assumptions!$B$114*D14 | E25: =-Assumptions!$B$114*E14 | F25: =-Assumptions!$B$114*F14 | G25: =-Assumptions!$B$114*G14
A26: FX losses (net) | C26: =-Assumptions!$B$115*C14 | D26: =-Assumptions!$B$115*D14 | E26: =-Assumptions!$B$115*E14 | F26: =-Assumptions!$B$115*F14 | G26: =-Assumptions!$B$115*G14
A27: Total operating costs | C27: =C17+C18+C19+C20+C21+C22+C23+C24+C25+C26 | D27: =D17+D18+D19+D20+D21+D22+D23+D24+D25+D26 | E27: =E17+E18+E19+E20+E21+E22+E23+E24+E25+E26 | F27: =F17+F18+F19+F20+F21+F22+F23+F24+F25+F26 | G27: =G17+G18+G19+G20+G21+G22+G23+G24+G25+G26
A28: EBITDA | C28: =C14+C27 | D28: =D14+D27 | E28: =E14+E27 | F28: =F14+F27 | G28: =G14+G27
A30: Depreciation (PP&E + right-of-use) | C30: =PPE!$C$39+Leases!$C$9 | D30: =PPE!$D$39+Leases!$D$9 | E30: =PPE!$E$39+Leases!$E$9 | F30: =PPE!$F$39+Leases!$F$9 | G30: =PPE!$G$39+Leases!$G$9
A31: Amortisation (intangibles + spectrum) | C31: =-Assumptions!$B$118*C14+Spectrum!$C$24 | D31: =-Assumptions!$B$118*D14+Spectrum!$D$24 | E31: =-Assumptions!$B$118*E14+Spectrum!$E$24 | F31: =-Assumptions!$B$118*F14+Spectrum!$F$24 | G31: =-Assumptions!$B$118*G14+Spectrum!$G$24
A32: EBIT | C32: =C28+C30+C31 | D32: =D28+D30+D31 | E32: =E28+E30+E31 | F32: =F28+F30+F31 | G32: =G28+G30+G31
A34: Finance income | C34: =Assumptions!$B$17*C14 | D34: =Assumptions!$B$17*D14 | E34: =Assumptions!$B$17*E14 | F34: =Assumptions!$B$17*F14 | G34: =Assumptions!$B$17*G14
A35: Finance costs (interest + lease interest) | C35: =-Debt!$C$45-Leases!$C$14 | D35: =-Debt!$D$45-Leases!$D$14 | E35: =-Debt!$E$45-Leases!$E$14 | F35: =-Debt!$F$45-Leases!$F$14 | G35: =-Debt!$G$45-Leases!$G$14
A36: Share of associates / JVs | C36: =Assumptions!$B$119*(1+Assumptions!$B$120)^1 | D36: =Assumptions!$B$119*(1+Assumptions!$B$120)^2 | E36: =Assumptions!$B$119*(1+Assumptions!$B$120)^3 | F36: =Assumptions!$B$119*(1+Assumptions!$B$120)^4 | G36: =Assumptions!$B$119*(1+Assumptions!$B$120)^5
A37: Profit before tax | C37: =C32+C34+C35+C36 | D37: =D32+D34+D35+D36 | E37: =E32+E34+E35+E36 | F37: =F32+F34+F35+F36 | G37: =G32+G34+G35+G36
A38: Current tax expense | C38: =-Tax!$C$9 | D38: =-Tax!$D$9 | E38: =-Tax!$E$9 | F38: =-Tax!$F$9 | G38: =-Tax!$G$9
A39: Deferred tax (movement) | C39: =-Tax!$C$15 | D39: =-Tax!$D$15 | E39: =-Tax!$E$15 | F39: =-Tax!$F$15 | G39: =-Tax!$G$15
A40: NET INCOME | C40: =C37+C38+C39 | D40: =D37+D38+D39 | E40: =E37+E38+E39 | F40: =F37+F38+F39 | G40: =G37+G38+G39
A42: Attributable to equity holders of the parent | C42: =C40*(1-Assumptions!$B$121) | D42: =D40*(1-Assumptions!$B$121) | E42: =E40*(1-Assumptions!$B$121) | F42: =F40*(1-Assumptions!$B$121) | G42: =G40*(1-Assumptions!$B$121)
A43: Attributable to minority interest | C43: =C40*Assumptions!$B$121 | D43: =D40*Assumptions!$B$121 | E43: =E40*Assumptions!$B$121 | F43: =F40*Assumptions!$B$121 | G43: =G40*Assumptions!$B$121
A45: Basic EPS (SAR / share) | C45: =C42*1000/Assumptions!$B$32 | D45: =D42*1000/Assumptions!$B$32 | E45: =E42*1000/Assumptions!$B$32 | F45: =F42*1000/Assumptions!$B$32 | G45: =G42*1000/Assumptions!$B$32
A47: MEMO
...

Sheet Segments
A1: SEGMENT P&L (contribution margin view)
A2: Each segment carries its own contribution margin (segment revenue × CM%). Difference vs. IS EBITDA = unallocated group overhead.
B4: Y0 (base) | C4: Y1 | D4: Y2 | E4: Y3 | F4: Y4 | G4: Y5
A6: REVENUE
A7: Mobile postpaid | B7: =Drivers!$B$31 | C7: =Drivers!$C$31 | D7: =Drivers!$D$31 | E7: =Drivers!$E$31 | F7: =Drivers!$F$31 | G7: =Drivers!$G$31
A8: Mobile prepaid | B8: =Drivers!$B$32 | C8: =Drivers!$C$32 | D8: =Drivers!$D$32 | E8: =Drivers!$E$32 | F8: =Drivers!$F$32 | G8: =Drivers!$G$32
A9: Fixed broadband | B9: =Drivers!$B$33 | C9: =Drivers!$C$33 | D9: =Drivers!$D$33 | E9: =Drivers!$E$33 | F9: =Drivers!$F$33 | G9: =Drivers!$G$33
A10: B2B connectivity | B10: =Drivers!$B$34 | C10: =Drivers!$C$34 | D10: =Drivers!$D$34 | E10: =Drivers!$E$34 | F10: =Drivers!$F$34 | G10: =Drivers!$G$34
A11: ICT / cloud | B11: =Drivers!$B$35 | C11: =Drivers!$C$35 | D11: =Drivers!$D$35 | E11: =Drivers!$E$35 | F11: =Drivers!$F$35 | G11: =Drivers!$G$35
A12: Wholesale | B12: =Drivers!$B$36 | C12: =Drivers!$C$36 | D12: =Drivers!$D$36 | E12: =Drivers!$E$36 | F12: =Drivers!$F$36 | G12: =Drivers!$G$36
A13: Equipment | B13: =Drivers!$B$39 | C13: =Drivers!$C$39 | D13: =Drivers!$D$39 | E13: =Drivers!$E$39 | F13: =Drivers!$F$39 | G13: =Drivers!$G$39
A14: Total service revenue | B14: =B7+B8+B9+B10+B11+B12 | C14: =C7+C8+C9+C10+C11+C12 | D14: =D7+D8+D9+D10+D11+D12 | E14: =E7+E8+E9+E10+E11+E12 | F14: =F7+F8+F9+F10+F11+F12 | G14: =G7+G8+G9+G10+G11+G12
A15: Total revenue (incl. equipment) | B15: =B7+B8+B9+B10+B11+B12+B13 | C15: =C7+C8+C9+C10+C11+C12+C13 | D15: =D7+D8+D9+D10+D11+D12+D13 | E15: =E7+E8+E9+E10+E11+E12+E13 | F15: =F7+F8+F9+F10+F11+F12+F13 | G15: =G7+G8+G9+G10+G11+G12+G13
A17: DIRECT COSTS (= revenue × (1 − CM%))
A18: Mobile postpaid | B18: =-B7*(1-Assumptions!$B$70) | C18: =-C7*(1-Assumptions!$B$70) | D18: =-D7*(1-Assumptions!$B$70) | E18: =-E7*(1-Assumptions!$B$70) | F18: =-F7*(1-Assumptions!$B$70) | G18: =-G7*(1-Assumptions!$B$70)
A19: Mobile prepaid | B19: =-B8*(1-Assumptions!$B$78) | C19: =-C8*(1-Assumptions!$B$78) | D19: =-D8*(1-Assumptions!$B$78) | E19: =-E8*(1-Assumptions!$B$78) | F19: =-F8*(1-Assumptions!$B$78) | G19: =-G8*(1-Assumptions!$B$78)
A20: Fixed broadband | B20: =-B9*(1-Assumptions!$B$86) | C20: =-C9*(1-Assumptions!$B$86) | D20: =-D9*(1-Assumptions!$B$86) | E20: =-E9*(1-Assumptions!$B$86) | F20: =-F9*(1-Assumptions!$B$86) | G20: =-G9*(1-Assumptions!$B$86)
A21: B2B connectivity | B21: =-B10*(1-Assumptions!$B$91) | C21: =-C10*(1-Assumptions!$B$91) | D21: =-D10*(1-Assumptions!$B$91) | E21: =-E10*(1-Assumptions!$B$91) | F21: =-F10*(1-Assumptions!$B$91) | G21: =-G10*(1-Assumptions!$B$91)
A22: ICT / cloud | B22: =-B11*(1-Assumptions!$B$96) | C22: =-C11*(1-Assumptions!$B$96) | D22: =-D11*(1-Assumptions!$B$96) | E22: =-E11*(1-Assumptions!$B$96) | F22: =-F11*(1-Assumptions!$B$96) | G22: =-G11*(1-Assumptions!$B$96)
A23: Wholesale | B23: =-B12*(1-Assumptions!$B$101) | C23: =-C12*(1-Assumptions!$B$101) | D23: =-D12*(1-Assumptions!$B$101) | E23: =-E12*(1-Assumptions!$B$101) | F23: =-F12*(1-Assumptions!$B$101) | G23: =-G12*(1-Assumptions!$B$101)
A24: Equipment | B24: =-B13*(1-Assumptions!$B$106) | C24: =-C13*(1-Assumptions!$B$106) | D24: =-D13*(1-Assumptions!$B$106) | E24: =-E13*(1-Assumptions!$B$106) | F24: =-F13*(1-Assumptions!$B$106) | G24: =-G13*(1-Assumptions!$B$106)
A25: Total direct costs | B25: =B18+B19+B20+B21+B22+B23+B24 | C25: =C18+C19+C20+C21+C22+C23+C24 | D25: =D18+D19+D20+D21+D22+D23+D24 | E25: =E18+E19+E20+E21+E22+E23+E24 | F25: =F18+F19+F20+F21+F22+F23+F24 | G25: =G18+G19+G20+G21+G22+G23+G24
A27: SEGMENT CONTRIBUTION
A28: Mobile postpaid | B28: =B7+B18 | C28: =C7+C18 | D28: =D7+D18 | E28: =E7+E18 | F28: =F7+F18 | G28: =G7+G18
A29: Mobile prepaid | B29: =B8+B19 | C29: =C8+C19 | D29: =D8+D19 | E29: =E8+E19 | F29: =F8+F19 | G29: =G8+G19
A30: Fixed broadband | B30: =B9+B20 | C30: =C9+C20 | D30: =D9+D20 | E30: =E9+E20 | F30: =F9+F20 | G30: =G9+G20
A31: B2B connectivity | B31: =B10+B21 | C31: =C10+C21 | D31: =D10+D21 | E31: =E10+E21 | F31: =F10+F21 | G31: =G10+G21
A32: ICT / cloud | B32: =B11+B22 | C32: =C11+C22 | D32: =D11+D22 | E32: =E11+E22 | F32: =F11+F22 | G32: =G11+G22
A33: Wholesale | B33: =B12+B23 | C33: =C12+C23 | D33: =D12+D23 | E33: =E12+E23 | F33: =F12+F23 | G33: =G12+G23
A34: Equipment | B34: =B13+B24 | C34: =C13+C24 | D34: =D13+D24 | E34: =E13+E24 | F34: =F13+F24 | G34: =G13+G24
A35: Aggregate segment contribution | B35: =B28+B29+B30+B31+B32+B33+B34 | C35: =C28+C29+C30+C31+C32+C33+C34 | D35: =D28+D29+D30+D31+D32+D33+D34 | E35: =E28+E29+E30+E31+E32+E33+E34 | F35: =F28+F29+F30+F31+F32+F33+F34 | G35: =G28+G29+G30+G31+G32+G33+G34
A37: CONTRIBUTION MARGIN %
A38: Mobile postpaid | B38: =IF(B7=0,0,B28/B7) | C38: =IF(C7=0,0,C28/C7) | D38: =IF(D7=0,0,D28/D7) | E38: =IF(E7=0,0,E28/E7) | F38: =IF(F7=0,0,F28/F7) | G38: =IF(G7=0,0,G28/G7)
A39: Mobile prepaid | B39: =IF(B8=0,0,B29/B8) | C39: =IF(C8=0,0,C29/C8) | D39: =IF(D8=0,0,D29/D8) | E39: =IF(E8=0,0,E29/E8) | F39: =IF(F8=0,0,F29/F8) | G39: =IF(G8=0,0,G29/G8)
A40: Fixed broadband | B40: =IF(B9=0,0,B30/B9) | C40: =IF(C9=0,0,C30/C9) | D40: =IF(D9=0,0,D30/D9) | E40: =IF(E9=0,0,E30/E9) | F40: =IF(F9=0,0,F30/F9) | G40: =IF(G9=0,0,G30/G9)
A41: B2B connectivity | B41: =IF(B10=0,0,B31/B10) | C41: =IF(C10=0,0,C31/C10) | D41: =IF(D10=0,0,D31/D10) | E41: =IF(E10=0,0,E31/E10) | F41: =IF(F10=0,0,F31/F10) | G41: =IF(G10=0,0,G31/G10)
A42: ICT / cloud | B42: =IF(B11=0,0,B32/B11) | C42: =IF(C11=0,0,C32/C11) | D42: =IF(D11=0,0,D32/D11) | E42: =IF(E11=0,0,E32/E11) | F42: =IF(F11=0,0,F32/F11) | G42: =IF(G11=0,0,G32/G11)
A43: Wholesale | B43: =IF(B12=0,0,B33/B12) | C43: =IF(C12=0,0,C33/C12) | D43: =IF(D12=0,0,D33/D12) | E43: =IF(E12=0,0,E33/E12) | F43: =IF(F12=0,0,F33/F12) | G43: =IF(G12=0,0,G33/G12)
A44: Equipment | B44: =IF(B13=0,0,B34/B13) | C44: =IF(C13=0,0,C34/C13) | D44: =IF(D13=0,0,D34/D13) | E44: =IF(E13=0,0,E34/E13) | F44: =IF(F13=0,0,F34/F13) | G44: =IF(G13=0,0,G34/G13)
A45: Blended CM % | B45: =B35/B15 | C45: =C35/C15 | D45: =D35/D15 | E45: =E35/E15 | F45: =F35/F15 | G45: =G35/G15
...

Sheet Equity
A1: EQUITY ROLLFORWARD
A2: Closing equity = opening + net income − dividends + OCI movements. Drives BS equity section.
B4: Y0 (base) | C4: Y1 | D4: Y2 | E4: Y3 | F4: Y4 | G4: Y5
A6: Share capital | B6: =Assumptions!$B$56 | C6: =B6 | D6: =C6 | E6: =D6 | F6: =E6 | G6: =F6
A7: Opening retained earnings | B7: "" | C7: =Assumptions!$B$57 | D7: =C10 | E7: =D10 | F7: =E10 | G7: =F10
A8: + Net income for period | B8: "" | C8: =IS!$C$40 | D8: =IS!$D$40 | E8: =IS!$E$40 | F8: =IS!$F$40 | G8: =IS!$G$40
A9: − Dividends paid | B9: "" | C9: =-Assumptions!$B$24*IS!$C$40 | D9: =-Assumptions!$B$24*IS!$D$40 | E9: =-Assumptions!$B$24*IS!$E$40 | F9: =-Assumptions!$B$24*IS!$F$40 | G9: =-Assumptions!$B$24*IS!$G$40
A10: Closing retained earnings | B10: =Assumptions!$B$57 | C10: =C7+C8+C9 | D10: =D7+D8+D9 | E10: =E7+E8+E9 | F10: =F7+F8+F9 | G10: =G7+G8+G9
A12: OCI reserve (held flat) | B12: =Assumptions!$B$58 | C12: =B12 | D12: =C12 | E12: =D12 | F12: =E12 | G12: =F12
A13: Minority interest (held flat) | B13: =Assumptions!$B$59 | C13: =B13 | D13: =C13 | E13: =D13 | F13: =E13 | G13: =F13
A15: TOTAL EQUITY | B15: =B6+B10+B12+B13 | C15: =C6+C10+C12+C13 | D15: =D6+D10+D12+D13 | E15: =E6+E10+E12+E13 | F15: =F6+F10+F12+F13 | G15: =G6+G10+G12+G13

Sheet BS
A1: BALANCE SHEET
A2: All figures in SAR billion. Y0 opening + Y1-Y5 forecast. Must balance (see Checks).
B4: Y0 (base) | C4: Y1 | D4: Y2 | E4: Y3 | F4: Y4 | G4: Y5
A6: ASSETS
A7: Cash & equivalents | B7: =Assumptions!$B$35 | C7: =B7+CFS!C26 | D7: =C7+CFS!D26 | E7: =D7+CFS!E26 | F7: =E7+CFS!F26 | G7: =F7+CFS!G26
A8: Accounts receivable | B8: =Assumptions!$B$36 | C8: =WC!$C$11 | D8: =WC!$D$11 | E8: =WC!$E$11 | F8: =WC!$F$11 | G8: =WC!$G$11
A9: Inventory | B9: =Assumptions!$B$37 | C9: =WC!$C$12 | D9: =WC!$D$12 | E9: =WC!$E$12 | F9: =WC!$F$12 | G9: =WC!$G$12
A10: Other current assets (flat) | B10: =Assumptions!$B$38 | C10: =B10 | D10: =C10 | E10: =D10 | F10: =E10 | G10: =F10
A11: Total current assets | B11: =B7+B8+B9+B10 | C11: =C7+C8+C9+C10 | D11: =D7+D8+D9+D10 | E11: =E7+E8+E9+E10 | F11: =F7+F8+F9+F10 | G11: =G7+G8+G9+G10
A13: Property, plant & equipment | B13: =Assumptions!$B$39 | C13: =PPE!$C$40 | D13: =PPE!$D$40 | E13: =PPE!$E$40 | F13: =PPE!$F$40 | G13: =PPE!$G$40
A14: Right-of-use assets (IFRS 16) | B14: =Leases!$B$10 | C14: =Leases!$C$10 | D14: =Leases!$D$10 | E14: =Leases!$E$10 | F14: =Leases!$F$10 | G14: =Leases!$G$10
A15: Goodwill (flat) | B15: =Assumptions!$B$40 | C15: =B15 | D15: =C15 | E15: =D15 | F15: =E15 | G15: =F15
A16: Spectrum licenses | B16: =Assumptions!$B$124+Assumptions!$B$126 | C16: =Spectrum!$C$23 | D16: =Spectrum!$D$23 | E16: =Spectrum!$E$23 | F16: =Spectrum!$F$23 | G16: =Spectrum!$G$23
A17: Other intangibles (less amortisation) | B17: =Assumptions!$B$142 | C17: =B17-Assumptions!$B$118*IS!$C$14 | D17: =C17-Assumptions!$B$118*IS!$D$14 | E17: =D17-Assumptions!$B$118*IS!$E$14 | F17: =E17-Assumptions!$B$118*IS!$F$14 | G17: =F17-Assumptions!$B$118*IS!$G$14
A18: Investments / associates (flat) | B18: =Assumptions!$B$42 | C18: =B18 | D18: =C18 | E18: =D18 | F18: =E18 | G18: =F18
A19: Deferred tax assets (flat) | B19: =Assumptions!$B$43 | C19: =B19 | D19: =C19 | E19: =D19 | F19: =E19 | G19: =F19
A20: Total non-current assets | B20: =B13+B14+B15+B16+B17+B18+B19 | C20: =C13+C14+C15+C16+C17+C18+C19 | D20: =D13+D14+D15+D16+D17+D18+D19 | E20: =E13+E14+E15+E16+E17+E18+E19 | F20: =F13+F14+F15+F16+F17+F18+F19 | G20: =G13+G14+G15+G16+G17+G18+G19
A22: TOTAL ASSETS | B22: =B11+B20 | C22: =C11+C20 | D22: =D11+D20 | E22: =E11+E20 | F22: =F11+F20 | G22: =G11+G20
A24: LIABILITIES
A25: Accounts payable | B25: =Assumptions!$B$46 | C25: =WC!$C$13 | D25: =WC!$D$13 | E25: =WC!$E$13 | F25: =WC!$F$13 | G25: =WC!$G$13
A26: Other current liabilities (flat) | B26: =Assumptions!$B$47 | C26: =B26 | D26: =C26 | E26: =D26 | F26: =E26 | G26: =F26
A27: Short-term debt | B27: =Debt!B35 | C27: =Debt!C35 | D27: =Debt!D35 | E27: =Debt!E35 | F27: =Debt!F35 | G27: =Debt!G35
A28: Total current liabilities | B28: =B25+B26+B27 | C28: =C25+C26+C27 | D28: =D25+D26+D27 | E28: =E25+E26+E27 | F28: =F25+F26+F27 | G28: =G25+G26+G27
A30: Long-term debt | B30: =Debt!B36 | C30: =Debt!C36 | D30: =Debt!D36 | E30: =Debt!E36 | F30: =Debt!F36 | G30: =Debt!G36
A31: Lease liabilities | B31: =Debt!B37 | C31: =Debt!C37 | D31: =Debt!D37 | E31: =Debt!E37 | F31: =Debt!F37 | G31: =Debt!G37
A32: Provisions (flat) | B32: =Assumptions!$B$51 | C32: =B32 | D32: =C32 | E32: =D32 | F32: =E32 | G32: =F32
A33: Deferred tax liabilities (rollforward) | B33: =Assumptions!$B$52 | C33: =Tax!$C$16 | D33: =Tax!$D$16 | E33: =Tax!$E$16 | F33: =Tax!$F$16 | G33: =Tax!$G$16
A34: Other non-current liabilities (flat) | B34: =Assumptions!$B$53 | C34: =B34 | D34: =C34 | E34: =D34 | F34: =E34 | G34: =F34
A35: Total non-current liabilities | B35: =B30+B31+B32+B33+B34 | C35: =C30+C31+C32+C33+C34 | D35: =D30+D31+D32+D33+D34 | E35: =E30+E31+E32+E33+E34 | F35: =F30+F31+F32+F33+F34 | G35: =G30+G31+G32+G33+G34
A37: TOTAL LIABILITIES | B37: =B28+B35 | C37: =C28+C35 | D37: =D28+D35 | E37: =E28+E35 | F37: =F28+F35 | G37: =G28+G35
A39: EQUITY
A40: Share capital | B40: =Equity!$B$6 | C40: =Equity!$C$6 | D40: =Equity!$D$6 | E40: =Equity!$E$6 | F40: =Equity!$F$6 | G40: =Equity!$G$6
A41: Retained earnings | B41: =Equity!$B$10 | C41: =Equity!$C$10 | D41: =Equity!$D$10 | E41: =Equity!$E$10 | F41: =Equity!$F$10 | G41: =Equity!$G$10
A42: OCI reserve | B42: =Equity!$B$12 | C42: =Equity!$C$12 | D42: =Equity!$D$12 | E42: =Equity!$E$12 | F42: =Equity!$F$12 | G42: =Equity!$G$12
A43: Minority interest | B43: =Equity!$B$13 | C43: =Equity!$C$13 | D43: =Equity!$D$13 | E43: =Equity!$E$13 | F43: =Equity!$F$13 | G43: =Equity!$G$13
A44: TOTAL EQUITY | B44: =Equity!$B$15 | C44: =Equity!$C$15 | D44: =Equity!$D$15 | E44: =Equity!$E$15 | F44: =Equity!$F$15 | G44: =Equity!$G$15
A46: Balance check (A − L − E) | B46: =B22-B37-B44 | C46: =C22-C37-C44 | D46: =D22-D37-D44 | E46: =E22-E37-E44 | F46: =F22-F37-F44 | G46: =G22-G37-G44

Sheet CFS
A1: CASH FLOW STATEMENT (indirect method)
A2: All figures in SAR billion. Net change in cash flows to BS.
C4: Y1 | D4: Y2 | E4: Y3 | F4: Y4 | G4: Y5
A6: OPERATING
A7: Net income | C7: =IS!$C$40 | D7: =IS!$D$40 | E7: =IS!$E$40 | F7: =IS!$F$40 | G7: =IS!$G$40
A8: + Depreciation (non-cash addback) | C8: =-IS!$C$30 | D8: =-IS!$D$30 | E8: =-IS!$E$30 | F8: =-IS!$F$30 | G8: =-IS!$G$30
A9: + Amortisation (non-cash addback) | C9: =-IS!$C$31 | D9: =-IS!$D$31 | E9: =-IS!$E$31 | F9: =-IS!$F$31 | G9: =-IS!$G$31
A10: + Deferred tax (non-cash addback) | C10: =Tax!$C$15 | D10: =Tax!$D$15 | E10: =Tax!$E$15 | F10: =Tax!$F$15 | G10: =Tax!$G$15
A11: +/− Δ working capital | C11: =WC!$C$20 | D11: =WC!$D$20 | E11: =WC!$E$20 | F11: =WC!$F$20 | G11: =WC!$G$20
A12: Cash from operations (CFO) | C12: =C7+C8+C9+C10+C11 | D12: =D7+D8+D9+D10+D11 | E12: =E7+E8+E9+E10+E11 | F12: =F7+F8+F9+F10+F11 | G12: =G7+G8+G9+G10+G11
A14: INVESTING
A15: − Capex (PP&E) | C15: =-PPE!$C$38 | D15: =-PPE!$D$38 | E15: =-PPE!$E$38 | F15: =-PPE!$F$38 | G15: =-PPE!$G$38
A16: − Spectrum cash payments | C16: =-Spectrum!$C$25 | D16: =-Spectrum!$D$25 | E16: =-Spectrum!$E$25 | F16: =-Spectrum!$F$25 | G16: =-Spectrum!$G$25
A17: Other investing (flat / nil) | C17: =0 | D17: =0 | E17: =0 | F17: =0 | G17: =0
A18: Cash from investing (CFI) | C18: =C15+C16+C17 | D18: =D15+D16+D17 | E18: =E15+E16+E17 | F18: =F15+F16+F17 | G18: =G15+G16+G17
A20: FINANCING
A21: +/− Net debt issuance (from Debt schedule) | C21: =Debt!$C$46 | D21: =Debt!$D$46 | E21: =Debt!$E$46 | F21: =Debt!$F$46 | G21: =Debt!$G$46
A22: − Lease cash payments | C22: =Leases!$C$16 | D22: =Leases!$D$16 | E22: =Leases!$E$16 | F22: =Leases!$F$16 | G22: =Leases!$G$16
A23: − Dividends paid | C23: =Equity!$C$9 | D23: =Equity!$D$9 | E23: =Equity!$E$9 | F23: =Equity!$F$9 | G23: =Equity!$G$9
A24: Cash from financing (CFF) | C24: =C21+C22+C23 | D24: =D21+D22+D23 | E24: =E21+E22+E23 | F24: =F21+F22+F23 | G24: =G21+G22+G23
A26: Net change in cash | C26: =C12+C18+C24 | D26: =D12+D18+D24 | E26: =E12+E18+E24 | F26: =F12+F18+F24 | G26: =G12+G18+G24
A27: Opening cash | C27: =Assumptions!$B$35 | D27: =C28 | E27: =D28 | F27: =E28 | G27: =F28
A28: Closing cash | C28: =C27+C26 | D28: =D27+D26 | E28: =E27+E26 | F28: =F27+F26 | G28: =G27+G26

Sheet Budget
A1: Y1 MONTHLY BUDGET
A2: Y1 P&L line items, distributed by month per the seasonality weights below. Variance columns are placeholders for actuals.
B4: Jan | C4: Feb | D4: Mar | E4: Apr | F4: May | G4: Jun | H4: Jul | I4: Aug | J4: Sep | K4: Oct | L4: Nov | M4: Dec | N4: Y1 Total
A5: Seasonality weight | B5: 0.081 | C5: 0.078 | D5: 0.082 | E5: 0.083 | F5: 0.082 | G5: 0.085 | H5: 0.082 | I5: 0.083 | J5: 0.084 | K5: 0.086 | L5: 0.087 | M5: 0.087 | N5: =SUM(B5:M5)
A7: P&L lines (SAR bn)
A8: Total revenue | B8: =B5*(IS!$C$14) | C8: =C5*(IS!$C$14) | D8: =D5*(IS!$C$14) | E8: =E5*(IS!$C$14) | F8: =F5*(IS!$C$14) | G8: =G5*(IS!$C$14) | H8: =H5*(IS!$C$14) | I8: =I5*(IS!$C$14) | ... M8: =M5*(IS!$C$14) | N8: =SUM(B8:M8)
A9: Service revenue | B9: =B5*(IS!$C$12) | C9: =C5*(IS!$C$12) | D9: =D5*(IS!$C$12) | E9: =E5*(IS!$C$12) | F9: =F5*(IS!$C$12) | G9: =G5*(IS!$C$12) | H9: =H5*(IS!$C$12) | I9: =I5*(IS!$C$12) | ... M9: =M5*(IS!$C$12) | N9: =SUM(B9:M9)
A10: Equipment revenue | B10: =B5*(IS!$C$13) | C10: =C5*(IS!$C$13) | D10: =D5*(IS!$C$13) | E10: =E5*(IS!$C$13) | F10: =F5*(IS!$C$13) | G10: =G5*(IS!$C$13) | H10: =H5*(IS!$C$13) | I10: =I5*(IS!$C$13) | ... M10: =M5*(IS!$C$13) | N10: =SUM(B10:M10)
A11: Interconnect & roaming | B11: =B5*(IS!$C$17) | C11: =C5*(IS!$C$17) | D11: =D5*(IS!$C$17) | E11: =E5*(IS!$C$17) | F11: =F5*(IS!$C$17) | G11: =G5*(IS!$C$17) | H11: =H5*(IS!$C$17) | I11: =I5*(IS!$C$17) | ... M11: =M5*(IS!$C$17) | N11: =SUM(B11:M11)
A12: Content / OTT | B12: =B5*(IS!$C$18) | C12: =C5*(IS!$C$18) | D12: =D5*(IS!$C$18) | E12: =E5*(IS!$C$18) | F12: =F5*(IS!$C$18) | G12: =G5*(IS!$C$18) | H12: =H5*(IS!$C$18) | I12: =I5*(IS!$C$18) | ... M12: =M5*(IS!$C$18) | N12: =SUM(B12:M12)
A13: Equipment COGS | B13: =B5*(IS!$C$19) | C13: =C5*(IS!$C$19) | D13: =D5*(IS!$C$19) | E13: =E5*(IS!$C$19) | F13: =F5*(IS!$C$19) | G13: =G5*(IS!$C$19) | H13: =H5*(IS!$C$19) | I13: =I5*(IS!$C$19) | ... M13: =M5*(IS!$C$19) | N13: =SUM(B13:M13)
A14: Network energy + lease | B14: =B5*(IS!$C$20) | C14: =C5*(IS!$C$20) | D14: =D5*(IS!$C$20) | E14: =E5*(IS!$C$20) | F14: =F5*(IS!$C$20) | G14: =G5*(IS!$C$20) | H14: =H5*(IS!$C$20) | I14: =I5*(IS!$C$20) | ... M14: =M5*(IS!$C$20) | N14: =SUM(B14:M14)
A15: Other network opex | B15: =B5*(IS!$C$21) | C15: =C5*(IS!$C$21) | D15: =D5*(IS!$C$21) | E15: =E5*(IS!$C$21) | F15: =F5*(IS!$C$21) | G15: =G5*(IS!$C$21) | H15: =H5*(IS!$C$21) | I15: =I5*(IS!$C$21) | ... M15: =M5*(IS!$C$21) | N15: =SUM(B15:M15)
A16: Employee costs | B16: =B5*(IS!$C$22) | C16: =C5*(IS!$C$22) | D16: =D5*(IS!$C$22) | E16: =E5*(IS!$C$22) | F16: =F5*(IS!$C$22) | G16: =G5*(IS!$C$22) | H16: =H5*(IS!$C$22) | I16: =I5*(IS!$C$22) | ... M16: =M5*(IS!$C$22) | N16: =SUM(B16:M16)
A17: Customer acquisition | B17: =B5*(IS!$C$23) | C17: =C5*(IS!$C$23) | D17: =D5*(IS!$C$23) | E17: =E5*(IS!$C$23) | F17: =F5*(IS!$C$23) | G17: =G5*(IS!$C$23) | H17: =H5*(IS!$C$23) | I17: =I5*(IS!$C$23) | ... M17: =M5*(IS!$C$23) | N17: =SUM(B17:M17)
A18: Other commercial | B18: =B5*(IS!$C$24) | C18: =C5*(IS!$C$24) | D18: =D5*(IS!$C$24) | E18: =E5*(IS!$C$24) | F18: =F5*(IS!$C$24) | G18: =G5*(IS!$C$24) | H18: =H5*(IS!$C$24) | I18: =I5*(IS!$C$24) | ... M18: =M5*(IS!$C$24) | N18: =SUM(B18:M18)
A19: G&A | B19: =B5*(IS!$C$25) | C19: =C5*(IS!$C$25) | D19: =D5*(IS!$C$25) | E19: =E5*(IS!$C$25) | F19: =F5*(IS!$C$25) | G19: =G5*(IS!$C$25) | H19: =H5*(IS!$C$25) | I19: =I5*(IS!$C$25) | ... M19: =M5*(IS!$C$25) | N19: =SUM(B19:M19)
A20: FX losses | B20: =B5*(IS!$C$26) | C20: =C5*(IS!$C$26) | D20: =D5*(IS!$C$26) | E20: =E5*(IS!$C$26) | F20: =F5*(IS!$C$26) | G20: =G5*(IS!$C$26) | H20: =H5*(IS!$C$26) | I20: =I5*(IS!$C$26) | ... M20: =M5*(IS!$C$26) | N20: =SUM(B20:M20)
A21: EBITDA | B21: =B5*(IS!$C$28) | C21: =C5*(IS!$C$28) | D21: =D5*(IS!$C$28) | E21: =E5*(IS!$C$28) | F21: =F5*(IS!$C$28) | G21: =G5*(IS!$C$28) | H21: =H5*(IS!$C$28) | I21: =I5*(IS!$C$28) | ... M21: =M5*(IS!$C$28) | N21: =SUM(B21:M21)
A22: Depreciation | B22: =B5*(IS!$C$30) | C22: =C5*(IS!$C$30) | D22: =D5*(IS!$C$30) | E22: =E5*(IS!$C$30) | F22: =F5*(IS!$C$30) | G22: =G5*(IS!$C$30) | H22: =H5*(IS!$C$30) | I22: =I5*(IS!$C$30) | ... M22: =M5*(IS!$C$30) | N22: =SUM(B22:M22)
A23: Amortisation | B23: =B5*(IS!$C$31) | C23: =C5*(IS!$C$31) | D23: =D5*(IS!$C$31) | E23: =E5*(IS!$C$31) | F23: =F5*(IS!$C$31) | G23: =G5*(IS!$C$31) | H23: =H5*(IS!$C$31) | I23: =I5*(IS!$C$31) | ... M23: =M5*(IS!$C$31) | N23: =SUM(B23:M23)
A24: EBIT | B24: =B5*(IS!$C$32) | C24: =C5*(IS!$C$32) | D24: =D5*(IS!$C$32) | E24: =E5*(IS!$C$32) | F24: =F5*(IS!$C$32) | G24: =G5*(IS!$C$32) | H24: =H5*(IS!$C$32) | I24: =I5*(IS!$C$32) | ... M24: =M5*(IS!$C$32) | N24: =SUM(B24:M24)
A25: Net income | B25: =B5*(IS!$C$40) | C25: =C5*(IS!$C$40) | D25: =D5*(IS!$C$40) | E25: =E5*(IS!$C$40) | F25: =F5*(IS!$C$40) | G25: =G5*(IS!$C$40) | H25: =H5*(IS!$C$40) | I25: =I5*(IS!$C$40) | ... M25: =M5*(IS!$C$40) | N25: =SUM(B25:M25)
A26: Attributable to parent | B26: =B5*(IS!$C$42) | C26: =C5*(IS!$C$42) | D26: =D5*(IS!$C$42) | E26: =E5*(IS!$C$42) | F26: =F5*(IS!$C$42) | G26: =G5*(IS!$C$42) | H26: =H5*(IS!$C$42) | I26: =I5*(IS!$C$42) | ... M26: =M5*(IS!$C$42) | N26: =SUM(B26:M26)
A27: Minority interest | B27: =B5*(IS!$C$43) | C27: =C5*(IS!$C$43) | D27: =D5*(IS!$C$43) | E27: =E5*(IS!$C$43) | F27: =F5*(IS!$C$43) | G27: =G5*(IS!$C$43) | H27: =H5*(IS!$C$43) | I27: =I5*(IS!$C$43) | ... M27: =M5*(IS!$C$43) | N27: =SUM(B27:M27)
A29: Quarterly summary
A30: Service revenue (quarterly) | B30: Q1 | C30: Q2 | D30: Q3 | E30: Q4
A31: Quarterly service revenue | B31: =B7+C7+D7 | C31: =E7+F7+G7 | D31: =H7+I7+J7 | E31: =K7+L7+M7

Sheet Scenarios
A1: SCENARIO MANAGER
A2: Reference table for downside / base / upside parameter sets. Active scenario set on Assumptions sheet.
B4: 1: Downside | C4: 2: Base | D4: 3: Upside
A6: Revenue growth | B6: 0.02 | C6: 0.06 | D6: 0.09
A7: EBITDA margin (target) | B7: 0.33 | C7: 0.36 | D7: 0.38
A8: Capex intensity | B8: 0.2 | C8: 0.18 | D8: 0.16
A10: Active scenario (1/2/3) | B10: =Assumptions!$B$62
A12: Active values (use INDEX in Assumptions to wire these)
A13: Note | B13: Manually overwrite Assumptions!B6/B7/B9 with these values, or build INDEX formulas. Kept manual for clarity.

Sheet Sensitivity
A1: SENSITIVITY TABLES
A2: Two-way tables on the key valuation levers. Outputs computed via TABLE-style formulas — change axis values to flex.
A4: Per-share value (SAR) — WACC × terminal growth
A5: WACC → | B5: 0.07 | C5: 0.08 | D5: 0.09 | E5: 0.1 | F5: 0.11
A6: 0.01 | B6: =((((IS!$C$32*(1-Assumptions!$B$20)+(-IS!$C$30)-PPE!$C$38+WC!$C$20)/(1+B5)^1)+((IS!$D$32*(1-Assumptions!$B$20)+(-IS!$D$30)-PPE!$D$38+WC!$D$20)/(1+B5)^2)+((IS!$E$32*(1-Assumptions!$B$20)+(-IS!$E$30)-PPE!$E$38+WC!$E$20)/(1+B5)^3)+((IS!$F$32*(1-Assumptions!$B$20)+(-IS!$F$30)-PPE!$F$38+WC!$F$20)/(1+B5)^4)+((IS!$G$32*(1-Assumptions!$B$20)+(-IS!$G$30)-PPE!$G$38+WC!$G$20)/(1+B5)^5)+(((IS!$G$32*(1-Assumptions!$B$20)+(-IS!$G$30)-PPE!$G$38+WC!$G$20)*(1+A6)/(B5-A6))/(1+B5)^5))-Debt!$B$43)*1000/Assumptions!$B$32 | C6: =((((IS!$C$32*(1-Assumptions!$B$20)+(-IS!$C$30)-PPE!$C$38+WC!$C$20)/(1+C5)^1)+((IS!$D$32*(1-Assumptions!$B$20)+(-IS!$D$30)-PPE!$D$38+WC!$D$20)/(1+C5)^2)+((IS!$E$32*(1-Assumptions!$B$20)+(-IS!$E$30)-PPE!$E$38+WC!$E$20)/(1+C5)^3)+((IS!$F$32*(1-Assumptions!$B$20)+(-IS!$F$30)-PPE!$F$38+WC!$F$20)/(1+C5)^4)+((IS!$G$32*(1-Assumptions!$B$20)+(-IS!$G$30)-PPE!$G$38+WC!$G$20)/(1+C5)^5)+(((IS!$G$32*(1-Assumptions!$B$20)+(-IS!$G$30)-PPE!$G$38+WC!$G$20)*(1+A6)/(C5-A6))/(1+C5)^5))-Debt!$B$43)*1000/Assumptions!$B$32 | D6: =((((IS!$C$32*(1-Assumptions!$B$20)+(-IS!$C$30)-PPE!$C$38+WC!$C$20)/(1+D5)^1)+((IS!$D$32*(1-Assumptions!$B$20)+(-IS!$D$30)-PPE!$D$38+WC!$D$20)/(1+D5)^2)+((IS!$E$32*(1-Assumptions!$B$20)+(-IS!$E$30)-PPE!$E$38+WC!$E$20)/(1+D5)^3)+((IS!$F$32*(1-Assumptions!$B$20)+(-IS!$F$30)-PPE!$F$38+WC!$F$20)/(1+D5)^4)+((IS!$G$32*(1-Assumptions!$B$20)+(-IS!$G$30)-PPE!$G$38+WC!$G$20)/(1+D5)^5)+(((IS!$G$32*(1-Assumptions!$B$20)+(-IS!$G$30)-PPE!$G$38+WC!$G$20)*(1+A6)/(D5-A6))/(1+D5)^5))-Debt!$B$43)*1000/Assumptions!$B$32 | E6: =((((IS!$C$32*(1-Assumptions!$B$20)+(-IS!$C$30)-PPE!$C$38+WC!$C$20)/(1+E5)^1)+((IS!$D$32*(1-Assumptions!$B$20)+(-IS!$D$30)-PPE!$D$38+WC!$D$20)/(1+E5)^2)+((IS!$E$32*(1-Assumptions!$B$20)+(-IS!$E$30)-PPE!$E$38+WC!$E$20)/(1+E5)^3)+((IS!$F$32*(1-Assumptions!$B$20)+(-IS!$F$30)-PPE!$F$38+WC!$F$20)/(1+E5)^4)+((IS!$G$32*(1-Assumptions!$B$20)+(-IS!$G$30)-PPE!$G$38+WC!$G$20)/(1+E5)^5)+(((IS!$G$32*(1-Assumptions!$B$20)+(-IS!$G$30)-PPE!$G$38+WC!$G$20)*(1+A6)/(E5-A6))/(1+E5)^5))-Debt!$B$43)*1000/Assumptions!$B$32 | F6: =((((IS!$C$32*(1-Assumptions!$B$20)+(-IS!$C$30)-PPE!$C$38+WC!$C$20)/(1+F5)^1)+((IS!$D$32*(1-Assumptions!$B$20)+(-IS!$D$30)-PPE!$D$38+WC!$D$20)/(1+F5)^2)+((IS!$E$32*(1-Assumptions!$B$20)+(-IS!$E$30)-PPE!$E$38+WC!$E$20)/(1+F5)^3)+((IS!$F$32*(1-Assumptions!$B$20)+(-IS!$F$30)-PPE!$F$38+WC!$F$20)/(1+F5)^4)+((IS!$G$32*(1-Assumptions!$B$20)+(-IS!$G$30)-PPE!$G$38+WC!$G$20)/(1+F5)^5)+(((IS!$G$32*(1-Assumptions!$B$20)+(-IS!$G$30)-PPE!$G$38+WC!$G$20)*(1+A6)/(F5-A6))/(1+F5)^5))-Debt!$B$43)*1000/Assumptions!$B$32
